2024-10-09 16:51:42,396 - Graphnet - ERROR - Error retrieving connections: Unable to retrieve routing information
Traceback (most recent call last):
  File "<stdin>", line 19, in get_connections
  File "/Muspelheim/PhD/02_second_study/01_code/classes/graphnet.py", line 45, in execute_query
    result = session.run(query, parameters)
             ^^^^^^^^^^^^^^^^^^^^^^^^^^^^^^
  File "/home/odin/miniconda3/envs/xmap_study_2/lib/python3.12/site-packages/neo4j/_sync/work/session.py", line 302, in run
    self._connect(self._config.default_access_mode)
  File "/home/odin/miniconda3/envs/xmap_study_2/lib/python3.12/site-packages/neo4j/_sync/work/session.py", line 130, in _connect
    super()._connect(
  File "/home/odin/miniconda3/envs/xmap_study_2/lib/python3.12/site-packages/neo4j/_sync/work/workspace.py", line 161, in _connect
    self._pool.update_routing_table(
  File "/home/odin/miniconda3/envs/xmap_study_2/lib/python3.12/site-packages/neo4j/_sync/io/_pool.py", line 804, in update_routing_table
    raise ServiceUnavailable("Unable to retrieve routing information")
neo4j.exceptions.ServiceUnavailable: Unable to retrieve routing information
